Workbook

Sheet Task Sprint 3
A1: SWP391 – TASK SHEET SPRINT 3 (20/10 → 02/11) – Flow 3 Payment & Report + SePay đối soát, làm sâu ngoại lệ Flow 1, 2, điểm danh, sửa UI
A2: BE: Nhanh (SePay) + Bảo · FE: Khôi + Khải (Khải nhiều UI nhất) · chia lại 14/10/2026 để Bảo, Khôi, Khải làm nhiều hơn · Business rule theo SWP391_UCP_Sprint_Role_Split · task Review có nhánh feature/f3-sepay-online-payment là Nhanh đã làm trước (PR #3) · UI-F1/UI-F2 là task sửa giao diện từ rà soát ảnh chụp 14/10
A4: Task ID | B4: US | C4: Function / Screen | D4: Loại | E4: Người làm | F4: Level | G4: Business Rule | H4: Nhánh | I4: Bắt đầu | J4: Hạn | K4: Trạng thái | L4: Ghi chú
A5: S3-01 | B5: UC-UM-12 | C5: BE – Gửi link đặt lại mật khẩu (màn S19): người dùng nhập email yêu cầu reset; hệ thống tạo link một lần và gửi thông báo mà không tiết lộ email có tồn tại hay không. | D5: BE | E5: Nhanh | F5: Medium | G5: Token reset là token một lần, hết hạn sau 15 phút theo BR-1.7. Hệ thống luôn trả thông báo chung kiểu “nếu email tồn tại đã gửi” để không dò tài khoản; không ghi token thô vào log. | H5: feature/f3-sepay-online-payment | I5: 20/10/2026 | J5: 02/11/2026 | K5: Review | L5: Kế hoạch: BE Bảo. Nhanh đã làm trước ở sprint bổ sung. Đã xong 14/10/2026, nằm trong PR #3 chờ review
A6: S3-02 | B6: UC-UM-12 | C6: FE – Gửi link đặt lại mật khẩu (màn S19): người dùng nhập email yêu cầu reset; hệ thống tạo link một lần và gửi thông báo mà không tiết lộ email có tồn tại hay không. | D6: FE | E6: Nhanh | F6: Medium | G6: Token reset là token một lần, hết hạn sau 15 phút theo BR-1.7. Hệ thống luôn trả thông báo chung kiểu “nếu email tồn tại đã gửi” để không dò tài khoản; không ghi token thô vào log. | H6: feature/f3-sepay-online-payment | I6: 20/10/2026 | J6: 02/11/2026 | K6: Review | L6: Kế hoạch: FE Khôi. Nhanh đã làm trước ở sprint bổ sung. Đã xong 14/10/2026, nằm trong PR #3 chờ review
A7: S3-03 | B7: UC-UM-12 | C7: BE – Đặt lại mật khẩu (màn S19): người dùng mở link còn hiệu lực và nhập mật khẩu mới; hệ thống xác nhận token trước khi cập nhật mật khẩu. | D7: BE | E7: Nhanh | F7: Medium | G7: Token phải còn hạn và chưa dùng; mật khẩu mới tối thiểu 8 ký tự và lưu mã hoá. Token sai/hết hạn/đã dùng bị từ chối; không lộ thông tin tài khoản. | H7: feature/f3-sepay-online-payment | I7: 20/10/2026 | J7: 02/11/2026 | K7: Review | L7: Kế hoạch: BE Bảo. Nhanh đã làm trước ở sprint bổ sung. Đã xong 14/10/2026, nằm trong PR #3 chờ review
A8: S3-04 | B8: UC-UM-12 | C8: FE – Đặt lại mật khẩu (màn S19): người dùng mở link còn hiệu lực và nhập mật khẩu mới; hệ thống xác nhận token trước khi cập nhật mật khẩu. | D8: FE | E8: Nhanh | F8: Medium | G8: Token phải còn hạn và chưa dùng; mật khẩu mới tối thiểu 8 ký tự và lưu mã hoá. Token sai/hết hạn/đã dùng bị từ chối; không lộ thông tin tài khoản. | H8: feature/f3-sepay-online-payment | I8: 20/10/2026 | J8: 02/11/2026 | K8: Review | L8: Kế hoạch: FE Khôi. Nhanh đã làm trước ở sprint bổ sung. Đã xong 14/10/2026, nằm trong PR #3 chờ review
A9: S3-05 | B9: UC-UM-04 | C9: BE – Chọn gói, tạo hoá đơn (online) (màn 14): Member chọn gói đang bán; hệ thống tạo hoặc tái sử dụng hoá đơn PENDING, sinh mã/QR và bắt đầu thời gian chờ thanh toán. | D9: BE | E9: Nhanh | F9: Medium | G9: BR-1.6: chỉ gói SELLING; BR-1.13/BR-PAY-12: mỗi member tối đa một invoice PENDING cho cùng gói và tái sử dụng invoice còn hạn. Mã invoice do server sinh duy nhất theo BR-PAY-01; timeout mặc định 15 phút theo BR-3.4. | H9: feature/f3-sepay-online-payment | I9: 20/10/2026 | J9: 02/11/2026 | K9: Review | L9: Nhanh đã làm ở sprint bổ sung. Đã xong 14/10/2026, nằm trong PR #3 chờ review
A10: S3-06 | B10: UC-UM-04 | C10: FE – Chọn gói, tạo hoá đơn (online) (màn 14): Member chọn gói đang bán; hệ thống tạo hoặc tái sử dụng hoá đơn PENDING, sinh mã/QR và bắt đầu thời gian chờ thanh toán. | D10: FE | E10: Nhanh | F10: Medium | G10: BR-1.6: chỉ gói SELLING; BR-1.13/BR-PAY-12: mỗi member tối đa một invoice PENDING cho cùng gói và tái sử dụng invoice còn hạn. Mã invoice do server sinh duy nhất theo BR-PAY-01; timeout mặc định 15 phút theo BR-3.4. | H10: feature/f3-sepay-online-payment | I10: 20/10/2026 | J10: 02/11/2026 | K10: Review | L10: Kế hoạch: FE Khải. Nhanh đã làm trước ở sprint bổ sung. Đã xong 14/10/2026, nằm trong PR #3 chờ review
A11: S3-07 | B11: UC-UM-10 | C11: BE – Job nhắc gia hạn: job định kỳ tìm membership sắp hết hạn và tạo thông báo nhắc gia hạn theo số ngày được cấu hình. Bổ sung: cùng job chuyển membership quá hạn sang EXPIRED và gửi thông báo "gói đã hết hạn" kèm nút gia hạn. | D11: BE | E11: Bảo | F11: Medium | G11: Số ngày nhắc lấy từ cấu hình. Mỗi membership chỉ được nhắc một lần; bỏ qua nếu hội viên đã gia hạn hoặc gói đã hết hạn theo BR-1.11. Job chạy theo ngày lịch và múi giờ Việt Nam, có log để chống gửi trùng. | H11: sprint-3/be-bao | I11: 20/10/2026 | J11: 02/11/2026 | K11: Review | L11: Mở rộng 14/10: cùng job chuyển membership quá hạn sang EXPIRED và gửi thông báo hết hạn. notification.service đã có dedupeKey.
A12: S3-08 | B12: UC-UM-15 | C12: BE – Xem nhật ký thao tác (màn S28): Manager tra cứu các thao tác quan trọng theo người thực hiện, thời gian, đối tượng và nội dung thay đổi. | D12: BE | E12: Khải | F12: Simple | G12: Manager tra cứu người thực hiện, thời điểm, đối tượng và nội dung thay đổi; audit log chỉ đọc. BR-0.2 yêu cầu ghi tạo/sửa/xoá mềm/đổi role/khoá/thu tiền/hoàn tiền/đổi cấu hình; audit log không bao giờ xoá theo BR-0.1. | H12: sprint-3/be-khai | I12: 20/10/2026 | J12: 02/11/2026 | K12: To Do | L12: Chia lại 14/10: chuyển BE từ Bảo sang Khải (full-stack, chức năng chỉ đọc; Bảo review).
A13: S3-09 | B13: UC-UM-15 | C13: FE – Xem nhật ký thao tác (màn S28): Manager tra cứu các thao tác quan trọng theo người thực hiện, thời gian, đối tượng và nội dung thay đổi. | D13: FE | E13: Khải | F13: Simple | G13: Manager tra cứu người thực hiện, thời điểm, đối tượng và nội dung thay đổi; audit log chỉ đọc. BR-0.2 yêu cầu ghi tạo/sửa/xoá mềm/đổi role/khoá/thu tiền/hoàn tiền/đổi cấu hình; audit log không bao giờ xoá theo BR-0.1. | H13: sprint-3/fe-khai | I13: 20/10/2026 | J13: 02/11/2026 | K13: To Do | L13: audit_logs đã được ghi ở hoá đơn, lớp, đăng ký; còn thiếu API đọc và màn xem
A14: S3-10 | B14: UC-CB-18 | C14: BE – Đổi giờ một buổi (màn S26): Manager đổi thời gian của một buổi chưa diễn ra; hệ thống kiểm tra xung đột và thông báo cho hội viên đang đăng ký. | D14: BE | E14: Bảo | F14: Medium | G14: Chỉ đổi buổi chưa diễn ra; lịch mới không trùng coach/phòng theo BR-2.4/2.8. Hội viên đang đăng ký nhận thông báo; nếu phát sinh trùng với booking khác thì chỉ cảnh báo và cho tự huỷ miễn phí, không tự huỷ theo BR-2.7/2.15. | H14: sprint-3/be-bao | I14: 20/10/2026 | J14: 02/11/2026 | K14: Review
A15: S3-11 | B15: UC-CB-18 | C15: FE – Đổi giờ một buổi (màn S26): Manager đổi thời gian của một buổi chưa diễn ra; hệ thống kiểm tra xung đột và thông báo cho hội viên đang đăng ký. | D15: FE | E15: Khôi | F15: Medium | G15: Chỉ đổi buổi chưa diễn ra; lịch mới không trùng coach/phòng theo BR-2.4/2.8. Hội viên đang đăng ký nhận thông báo; nếu phát sinh trùng với booking khác thì chỉ cảnh báo và cho tự huỷ miễn phí, không tự huỷ theo BR-2.7/2.15. | H15: sprint-3/fe-khoi | I15: 20/10/2026 | J15: 02/11/2026 | K15: Review | L15: Rà soát UI 14/10 (a-13): bảng "Các buổi học" chưa có cột thao tác, chưa có API từng buổi; làm cùng F2-08.
A16: S3-12 | B16: UC-CB-18 | C16: BE – Huỷ một buổi (màn S26): Manager/job huỷ một buổi chưa diễn ra, giữ lại lịch sử, ngăn điểm danh và thông báo cho hội viên bị ảnh hưởng. | D16: BE | E16: Bảo | F16: Medium | G16: Chuyển buổi sang CANCELLED nhưng giữ bản ghi lịch sử và không cho điểm danh. Gửi một thông báo cho tất cả hội viên đang đăng ký; không xoá cứng theo BR-0.1 và không gửi trùng theo BR-2.7. | H16: sprint-3/be-bao | I16: 20/10/2026 | J16: 02/11/2026 | K16: Review
A17: S3-13 | B17: UC-CB-18 | C17: FE – Huỷ một buổi (màn S26): Manager/job huỷ một buổi chưa diễn ra, giữ lại lịch sử, ngăn điểm danh và thông báo cho hội viên bị ảnh hưởng. | D17: FE | E17: Khôi | F17: Medium | G17: Chuyển buổi sang CANCELLED nhưng giữ bản ghi lịch sử và không cho điểm danh. Gửi một thông báo cho tất cả hội viên đang đăng ký; không xoá cứng theo BR-0.1 và không gửi trùng theo BR-2.7. | H17: sprint-3/fe-khoi | I17: 20/10/2026 | J17: 02/11/2026 | K17: Review | L17: Rà soát UI 14/10 (a-13): thêm nút "Huỷ buổi" kèm lý do và cảnh báo "sẽ thông báo N hội viên".
A18: S3-14 | B18: UC-PAY-01 | C18: BE – Màn QR và theo dõi trạng thái (màn 15): Member xem QR, nội dung chuyển khoản, trạng thái và đồng hồ hết hạn của hoá đơn online. | D18: BE | E18: Nhanh | F18: Medium | G18: Nội dung chuyển khoản phải chứa mã invoice theo BR-3.3; trạng thái theo BR-3.1 và timeout lấy từ cấu hình. Chỉ chủ invoice được xem/huỷ khi còn PENDING; hết hạn thì chờ job chuyển FAILED. | H18: feature/f3-sepay-online-payment | I18: 20/10/2026 | J18: 02/11/2026 | K18: Review | L18: Nhanh đã làm ở sprint bổ sung. Đã xong 14/10/2026, nằm trong PR #3 chờ review
A19: S3-15 | B19: UC-PAY-01 | C19: FE – Màn QR và theo dõi trạng thái (màn 15): Member xem QR, nội dung chuyển khoản, trạng thái và đồng hồ hết hạn của hoá đơn online. | D19: FE | E19: Nhanh | F19: Medium | G19: Nội dung chuyển khoản phải chứa mã invoice theo BR-3.3; trạng thái theo BR-3.1 và timeout lấy từ cấu hình. Chỉ chủ invoice được xem/huỷ khi còn PENDING; hết hạn thì chờ job chuyển FAILED. | H19: feature/f3-sepay-online-payment | I19: 20/10/2026 | J19: 02/11/2026 | K19: Review | L19: Kế hoạch: FE Khải. Nhanh đã làm trước ở sprint bổ sung. Đã xong 14/10/2026, nằm trong PR #3 chờ review
A20: S3-16 | B20: UC-PAY-02 | C20: BE – Xử lý webhook SePay: backend nhận giao dịch, xác thực chữ ký/API key, bóc mã hoá đơn, kiểm tra số tiền và cập nhật payment/invoice một cách idempotent. | D20: BE | E20: Nhanh | F20: Medium | G20: Phải xác thực Authorization bằng SEPAY_WEBHOOK_API_KEY; bóc mã từ code, nếu rỗng thì dùng regex trên content. Chỉ transferType=in và số tiền khớp tuyệt đối mới PAID/kích hoạt; giao dịch trùng idempotent, lệch tiền hoặc invoice không hợp lệ vào hàng chờ; log raw đã che secret và chỉ trả 200 sau commit theo BR-PAY-02 đến BR-PAY-10. | H20: feature/f3-sepay-online-payment | I20: 20/10/2026 | J20: 02/11/2026 | K20: Review | L20: Nhanh đã làm ở sprint bổ sung. Đã xong 14/10/2026, nằm trong PR #3 chờ review
A21: S3-17 | B21: UC-PAY-04 | C21: BE – Job hết hạn hoá đơn: job định kỳ tìm hoá đơn online PENDING quá thời gian chờ và chuyển sang FAILED nếu trạng thái vẫn còn PENDING. | D21: BE | E21: Nhanh | F21: Medium | G21: Chỉ chuyển invoice PENDING quá timeout cấu hình, mặc định 15 phút, sang FAILED. Webhook đến sau hoặc chuyển lặp không bị nuốt mà vào hàng chờ với lý do LATE/ALREADY_PROCESSED theo BR-3.4/BR-PAY-08. | H21: sprint-3/be-nhanh | I21: 20/10/2026 | J21: 02/11/2026 | K21: Review | L21: BE xong 14/10/2026 trên sprint-3/be-nhanh, 143 test BE pass; chờ review/merge
A22: S3-18 | B22: UC-PAY-05 | C22: BE – Xác nhận thanh toán thủ công (màn S29): Manager nhập mã tham chiếu và số tiền thực nhận để xác nhận khoản tiền ngoài webhook rồi cập nhật payment. Màn này là "Hàng chờ đối soát" chung cho mọi giao dịch SePay không tự khớp (xem #88–#94). | D22: BE | E22: Nhanh | F22: Medium | G22: Manager nhập mã tham chiếu và số tiền thực nhận; invoice phải ở trạng thái phù hợp và thao tác phải idempotent. Chỉ PAID mới kích hoạt/gia hạn; ghi lý do, người duyệt và audit; trạng thái đã đổi trả 409 theo BR-3.2/BR-PAY-07/13. | H22: sprint-3/be-nhanh | I22: 20/10/2026 | J22: 02/11/2026 | K22: Review | L22: BE xong 14/10/2026 trên sprint-3/be-nhanh, 143 test BE pass; chờ review/merge
A23: S3-19 | B23: UC-PAY-05 | C23: FE – Xác nhận thanh toán thủ công (màn S29): Manager nhập mã tham chiếu và số tiền thực nhận để xác nhận khoản tiền ngoài webhook rồi cập nhật payment. Màn này là "Hàng chờ đối soát" chung cho mọi giao dịch SePay không tự khớp (xem #88–#94). | D23: FE | E23: Khải | F23: Medium | G23: Manager nhập mã tham chiếu và số tiền thực nhận; invoice phải ở trạng thái phù hợp và thao tác phải idempotent. Chỉ PAID mới kích hoạt/gia hạn; ghi lý do, người duyệt và audit; trạng thái đã đổi trả 409 theo BR-3.2/BR-PAY-07/13. | H23: sprint-3/fe-khai | I23: 20/10/2026 | J23: 02/11/2026 | K23: To Do | L23: Mở rộng 14/10: đây là màn "Hàng chờ đối soát" chung; các màn #88, #90–92 mở từ đây.
A24: S3-20 | B24: UC-PAY-08 | C24: BE – Lịch sử giao dịch (màn 18): hội viên hoặc nhân viên xem danh sách invoice/payment trong phạm vi quyền, trạng thái và khả năng tiếp tục thanh toán. | D24: BE | E24: Nhanh | F24: Simple | G24: Member chỉ thấy giao dịch của mình; nhân viên chỉ thấy phạm vi được cấp. Invoice PENDING còn hạn có nút tiếp tục thanh toán; không xoá lịch sử trạng thái và payment, kể cả FAILED/REFUNDED. | H24: sprint-3/be-nhanh | I24: 20/10/2026 | J24: 02/11/2026 | K24: Review | L24: BE xong 14/10/2026 trên sprint-3/be-nhanh, 143 test BE pass; chờ review/merge
A25: S3-21 | B25: UC-PAY-08 | C25: FE – Lịch sử giao dịch (màn 18): hội viên hoặc nhân viên xem danh sách invoice/payment trong phạm vi quyền, trạng thái và khả năng tiếp tục thanh toán. | D25: FE | E25: Khải | F25: Simple | G25: Member chỉ thấy giao dịch của mình; nhân viên chỉ thấy phạm vi được cấp. Invoice PENDING còn hạn có nút tiếp tục thanh toán; không xoá lịch sử trạng thái và payment, kể cả FAILED/REFUNDED. | H25: sprint-3/fe-khai | I25: 20/10/2026 | J25: 02/11/2026 | K25: To Do | L25: Đã có danh sách hoá đơn lọc theo kênh, chi tiết và biên lai; chưa có bảng thanh toán (payments)
A26: S3-22 | B26: UC-PAY-09 | C26: BE – Hoàn tiền (màn S30): Manager chọn giao dịch đủ điều kiện, nhập lý do và mã tham chiếu rồi chuyển trạng thái hoàn tiền và cập nhật membership liên quan. | D26: BE | E26: Nhanh | F26: Medium | G26: Chỉ Manager được hoàn tiền cho invoice PAID, phải nhập lý do và mã tham chiếu. Chuyển PAID -> REFUNDED, số hoàn không vượt số đã nhận; tiền được trả thủ công ngoài hệ thống, membership liên quan được cập nhật và mọi thay đổi ghi audit theo BR-PAY-13/BR-0.2. | H26: sprint-3/be-nhanh | I26: 20/10/2026 | J26: 02/11/2026 | K26: Review | L26: BE xong 14/10/2026 trên sprint-3/be-nhanh, 143 test BE pass; chờ review/merge
A27: S3-23 | B27: UC-PAY-09 | C27: FE – Hoàn tiền (màn S30): Manager chọn giao dịch đủ điều kiện, nhập lý do và mã tham chiếu rồi chuyển trạng thái hoàn tiền và cập nhật membership liên quan. | D27: FE | E27: Khôi | F27: Medium | G27: Chỉ Manager được hoàn tiền cho invoice PAID, phải nhập lý do và mã tham chiếu. Chuyển PAID -> REFUNDED, số hoàn không vượt số đã nhận; tiền được trả thủ công ngoài hệ thống, membership liên quan được cập nhật và mọi thay đổi ghi audit theo BR-PAY-13/BR-0.2. | H27: sprint-3/fe-khoi | I27: 20/10/2026 | J27: 02/11/2026 | K27: Review | L27: Chia lại 14/10: FE chuyển từ Khải sang Khôi để Khải nhận màn đối soát. Cần nhóm chốt: hoàn toàn bộ thì trừ lại số ngày đã cộng vào membership.
A28: S3-24 | B28: UC-RPT-01 | C28: BE – Dashboard báo cáo (màn 17): Manager xem doanh thu, payment, membership và lớp theo bộ lọc; hệ thống tổng hợp dữ liệu đã thanh toán và hoàn tiền. | D28: BE | E28: Bảo | F28: Medium | G28: Chỉ permission report.view; doanh thu tính theo thời điểm PAID, trừ REFUNDED, không tính PENDING/FAILED và dùng ngày lịch Việt Nam theo BR-3.5/BR-0.3. Bộ lọc phải nhất quán giữa các chỉ số và không lộ dữ liệu ngoài quyền. | H28: sprint-3/be-bao | I28: 20/10/2026 | J28: 02/11/2026 | K28: Review | L28: Chưa có GET /reports/*
A29: S3-25 | B29: UC-RPT-01 | C29: FE – Dashboard báo cáo (màn 17): Manager xem doanh thu, payment, membership và lớp theo bộ lọc; hệ thống tổng hợp dữ liệu đã thanh toán và hoàn tiền. | D29: FE | E29: Khôi | F29: Medium | G29: Chỉ permission report.view; doanh thu tính theo thời điểm PAID, trừ REFUNDED, không tính PENDING/FAILED và dùng ngày lịch Việt Nam theo BR-3.5/BR-0.3. Bộ lọc phải nhất quán giữa các chỉ số và không lộ dữ liệu ngoài quyền. | H29: sprint-3/fe-khoi | I29: 20/10/2026 | J29: 02/11/2026 | K29: Review | L29: Chưa có GET /reports/*
A30: S3-26 | B30: UC-RPT-01 | C30: BE – Xuất tệp báo cáo (màn 17): Manager xuất PDF/CSV/Excel theo đúng bộ lọc đang xem, dùng cùng tập dữ liệu và công thức với dashboard. | D30: BE | E30: Bảo | F30: Medium | G30: Chỉ permission report.view; tệp xuất phải dùng đúng tập dữ liệu, bộ lọc và công thức đang hiển thị trên dashboard. Không cho client tự sửa số tiền; việc xuất có thể được ghi audit theo chính sách. | H30: sprint-3/be-bao | I30: 20/10/2026 | J30: 02/11/2026 | K30: Review
A31: S3-27 | B31: UC-RPT-01 | C31: FE – Xuất tệp báo cáo (màn 17): Manager xuất PDF/CSV/Excel theo đúng bộ lọc đang xem, dùng cùng tập dữ liệu và công thức với dashboard. | D31: FE | E31: Khôi | F31: Medium | G31: Chỉ permission report.view; tệp xuất phải dùng đúng tập dữ liệu, bộ lọc và công thức đang hiển thị trên dashboard. Không cho client tự sửa số tiền; việc xuất có thể được ghi audit theo chính sách. | H31: sprint-3/fe-khoi | I31: 20/10/2026 | J31: 02/11/2026 | K31: Review
A32: S3-28 | B32: UC-UM-01 | C32: BE – Bắt xác minh email trước khi vào hệ thống (màn 1, S19): đăng nhập đúng mật khẩu nhưng email chưa xác minh bị chặn; hội viên gửi lại và xác nhận link xác minh. | D32: BE | E32: Nhanh | F32: Medium | G32: Trả 403 EMAIL_NOT_VERIFIED sau khi kiểm tra mật khẩu. Token băm, dùng một lần, hạn theo EMAIL_VERIFICATION_TTL_MINUTES; gửi lại có giới hạn tần suất. Tài khoản chỉ có SĐT hoặc do nhân viên tạo coi là đã xác minh. | H32: feature/f3-sepay-online-payment | I32: 13/10/2026 | J32: 14/10/2026 | K32: Review | L32: Bổ sung ngoài kế hoạch gốc. Đã xong 14/10/2026, nằm trong PR #3 chờ review
A33: S3-29 | B33: UC-UM-01 | C33: FE – Bắt xác minh email trước khi vào hệ thống (màn 1, S19): đăng nhập đúng mật khẩu nhưng email chưa xác minh bị chặn; hội viên gửi lại và xác nhận link xác minh. | D33: FE | E33: Nhanh | F33: Medium | G33: Trả 403 EMAIL_NOT_VERIFIED sau khi kiểm tra mật khẩu. Token băm, dùng một lần, hạn theo EMAIL_VERIFICATION_TTL_MINUTES; gửi lại có giới hạn tần suất. Tài khoản chỉ có SĐT hoặc do nhân viên tạo coi là đã xác minh. | H33: feature/f3-sepay-online-payment | I33: 13/10/2026 | J33: 14/10/2026 | K33: Review | L33: Bổ sung ngoài kế hoạch gốc. Đã xong 14/10/2026, nằm trong PR #3 chờ review
A34: S3-30 | B34: UC-UM-02 | C34: BE – Đổi email có xác nhận (màn S20): email mới chỉ có hiệu lực sau khi bấm link gửi tới địa chỉ mới. | D34: BE | E34: Nhanh | F34: Medium | G34: BR-1.1: email duy nhất. Email cũ vẫn dùng đến khi xác nhận (pendingEmail); token băm, dùng một lần. | H34: feature/f3-sepay-online-payment | I34: 13/10/2026 | J34: 14/10/2026 | K34: Review | L34: Bổ sung ngoài kế hoạch gốc. Đã xong 14/10/2026, nằm trong PR #3 chờ review
A35: S3-31 | B35: UC-UM-02 | C35: FE – Đổi email có xác nhận (màn S20): email mới chỉ có hiệu lực sau khi bấm link gửi tới địa chỉ mới. | D35: FE | E35: Nhanh | F35: Medium | G35: BR-1.1: email duy nhất. Email cũ vẫn dùng đến khi xác nhận (pendingEmail); token băm, dùng một lần. | H35: feature/f3-sepay-online-payment | I35: 13/10/2026 | J35: 14/10/2026 | K35: Review | L35: Bổ sung ngoài kế hoạch gốc. Đã xong 14/10/2026, nằm trong PR #3 chờ review
A36: S3-32 | B36: UC-UM-19 | C36: BE – Nhân viên xác minh email thủ công (màn S22): lễ tân hoặc quản lý xác minh khi hội viên không nhận được email. | D36: BE | E36: Nhanh | F36: Simple | G36: Chỉ người có permission user.verify_email (không so sánh tên role); ghi nhật ký người thực hiện. | H36: feature/f3-sepay-online-payment | I36: 13/10/2026 | J36: 14/10/2026 | K36: Review | L36: Bổ sung ngoài kế hoạch gốc. Đã xong 14/10/2026, nằm trong PR #3 chờ review
A37: S3-33 | B37: UC-UM-19 | C37: FE – Nhân viên xác minh email thủ công (màn S22): lễ tân hoặc quản lý xác minh khi hội viên không nhận được email. | D37: FE | E37: Nhanh | F37: Simple | G37: Chỉ người có permission user.verify_email (không so sánh tên role); ghi nhật ký người thực hiện. | H37: feature/f3-sepay-online-payment | I37: 13/10/2026 | J37: 14/10/2026 | K37: Review | L37: Bổ sung ngoài kế hoạch gốc. Đã xong 14/10/2026, nằm trong PR #3 chờ review
A38: S3-34 | B38: UC-UM-12 | C38: BE – Liên hệ hỗ trợ khi không nhận được email (màn S19): hiển thị Zalo, Facebook, điện thoại trung tâm. | D38: BE | E38: Nhanh | F38: Simple | G38: Link Zalo và Facebook đọc từ system_settings (CENTER_SUPPORT_ZALO_URL, CENTER_SUPPORT_FACEBOOK_URL), kiểm tra định dạng URL; chỉ hiện kênh đã cấu hình; không trả dữ liệu nhạy cảm. | H38: feature/f3-sepay-online-payment | I38: 13/10/2026 | J38: 14/10/2026 | K38: Review | L38: Bổ sung ngoài kế hoạch gốc. Đã xong 14/10/2026, nằm trong PR #3 chờ review
A39: S3-35 | B39: UC-UM-12 | C39: FE – Liên hệ hỗ trợ khi không nhận được email (màn S19): hiển thị Zalo, Facebook, điện thoại trung tâm. | D39: FE | E39: Nhanh | F39: Simple | G39: Link Zalo và Facebook đọc từ system_settings (CENTER_SUPPORT_ZALO_URL, CENTER_SUPPORT_FACEBOOK_URL), kiểm tra định dạng URL; chỉ hiện kênh đã cấu hình; không trả dữ liệu nhạy cảm. | H39: feature/f3-sepay-online-payment | I39: 13/10/2026 | J39: 14/10/2026 | K39: Review | L39: Bổ sung ngoài kế hoạch gốc. Đã xong 14/10/2026, nằm trong PR #3 chờ review
A40: S3-36 | B40: UC-UM-16 | C40: BE – Cấu hình tài khoản nhận tiền SePay động (màn S27): mỗi thành viên nhập tài khoản SePay test riêng. | D40: BE | E40: Nhanh | F40: Simple | G40: Không hardcode: PAYMENT_BANK_CODE, PAYMENT_BANK_ACCOUNT_NUMBER, PAYMENT_BANK_ACCOUNT_NAME trong system_settings; chỉ SEPAY_WEBHOOK_API_KEY ở .env; kiểm tra định dạng mã ngân hàng và số tài khoản. Form Cài đặt dựng từ schema dùng chung nên không có FE riêng. | H40: feature/f3-sepay-online-payment | I40: 13/10/2026 | J40: 14/10/2026 | K40: Review | L40: Bổ sung ngoài kế hoạch gốc. Đã xong 14/10/2026, nằm trong PR #3 chờ review
A41: S3-37 | B41: UC-PAY-06 | C41: BE – Phân biệt kênh hoá đơn ONLINE và COUNTER (màn 16): cột và bộ lọc kênh; hộp thu tiền hiển thị trước tác động lên gói. | D41: BE | E41: Nhanh | F41: Medium | G41: Kênh gán lúc tạo: hội viên tự mua là ONLINE, lễ tân tạo là COUNTER. Một gói không có đồng thời hoá đơn PENDING khác kênh cho cùng hội viên. Hiển thị trước gói cộng dồn (còn hạn) hay bắt đầu mới (hết hạn) theo BR-1.3 và BR-1.4. | H41: feature/f3-sepay-online-payment | I41: 13/10/2026 | J41: 14/10/2026 | K41: Review | L41: Bổ sung ngoài kế hoạch gốc. Đã xong 14/10/2026, nằm trong PR #3 chờ review
...

Sheet Tổng hợp
A1: Tiến độ Sprint 3 theo thành viên
A3: Thành viên | B3: Vai | C3: Tổng task | D3: To Do | E3: In Progress | F3: Review | G3: Done | H3: % Done
A4: Nhanh | B4: BE · Leader | C4: =COUNTIF('Task Sprint 3'!$E$5:$E$123,A4) | D4: =COUNTIFS('Task Sprint 3'!$E$5:$E$123,$A4,'Task Sprint 3'!$K$5:$K$123,"To Do") | E4: =COUNTIFS('Task Sprint 3'!$E$5:$E$123,$A4,'Task Sprint 3'!$K$5:$K$123,"In Progress") | F4: =COUNTIFS('Task Sprint 3'!$E$5:$E$123,$A4,'Task Sprint 3'!$K$5:$K$123,"Review") | G4: =COUNTIFS('Task Sprint 3'!$E$5:$E$123,$A4,'Task Sprint 3'!$K$5:$K$123,"Done") | H4: =IF(C4=0,0,G4/C4)
A5: Bảo | B5: BE | C5: =COUNTIF('Task Sprint 3'!$E$5:$E$123,A5) | D5: =COUNTIFS('Task Sprint 3'!$E$5:$E$123,$A5,'Task Sprint 3'!$K$5:$K$123,"To Do") | E5: =COUNTIFS('Task Sprint 3'!$E$5:$E$123,$A5,'Task Sprint 3'!$K$5:$K$123,"In Progress") | F5: =COUNTIFS('Task Sprint 3'!$E$5:$E$123,$A5,'Task Sprint 3'!$K$5:$K$123,"Review") | G5: =COUNTIFS('Task Sprint 3'!$E$5:$E$123,$A5,'Task Sprint 3'!$K$5:$K$123,"Done") | H5: =IF(C5=0,0,G5/C5)
A6: Khôi | B6: FE | C6: =COUNTIF('Task Sprint 3'!$E$5:$E$123,A6) | D6: =COUNTIFS('Task Sprint 3'!$E$5:$E$123,$A6,'Task Sprint 3'!$K$5:$K$123,"To Do") | E6: =COUNTIFS('Task Sprint 3'!$E$5:$E$123,$A6,'Task Sprint 3'!$K$5:$K$123,"In Progress") | F6: =COUNTIFS('Task Sprint 3'!$E$5:$E$123,$A6,'Task Sprint 3'!$K$5:$K$123,"Review") | G6: =COUNTIFS('Task Sprint 3'!$E$5:$E$123,$A6,'Task Sprint 3'!$K$5:$K$123,"Done") | H6: =IF(C6=0,0,G6/C6)
A7: Khải | B7: FE | C7: =COUNTIF('Task Sprint 3'!$E$5:$E$123,A7) | D7: =COUNTIFS('Task Sprint 3'!$E$5:$E$123,$A7,'Task Sprint 3'!$K$5:$K$123,"To Do") | E7: =COUNTIFS('Task Sprint 3'!$E$5:$E$123,$A7,'Task Sprint 3'!$K$5:$K$123,"In Progress") | F7: =COUNTIFS('Task Sprint 3'!$E$5:$E$123,$A7,'Task Sprint 3'!$K$5:$K$123,"Review") | G7: =COUNTIFS('Task Sprint 3'!$E$5:$E$123,$A7,'Task Sprint 3'!$K$5:$K$123,"Done") | H7: =IF(C7=0,0,G7/C7)
A8: Tổng | C8: =SUM(C4:C7) | D8: =SUM(D4:D7) | E8: =SUM(E4:E7) | F8: =SUM(F4:F7) | G8: =SUM(G4:G7) | H8: =IF(C8=0,0,G8/C8)
A10: Demo main flow Sprint 3 (Review 3):
A11: 1. Hội viên chọn gói → xác nhận ngày hiệu lực → QR → chuyển khoản → webhook SePay → Đã thanh toán → tải hoá đơn PDF
A12: 2. Đối soát: chuyển sai mã → Manager map vào hội viên/gói; chuyển thiếu → hội viên chuyển bù bằng QR phần thiếu → PAID → xuất hoá đơn
A13: 3. Chuyển thừa → xác nhận + hoàn phần thừa; chuyển 2 lần cùng mã → cảnh báo đỏ → ghi nhật ký liên hệ → hoàn hoặc dùng gia hạn
A14: 4. Lỗi mạng/webhook chậm: hội viên bấm "Tôi đã chuyển khoản" → Manager đối chiếu → map; job hết hạn hoá đơn, job nhắc/hết hạn gói
A15: 5. Flow 1 sâu: khoá đăng nhập sau 5 lần sai; đăng ký tại quầy trùng SĐT → mở hồ sơ có sẵn; bảo lưu gói; khoá hội viên có lịch
A16: 6. Flow 2 sâu: lớp đầy → danh sách chờ; đổi giờ/huỷ một buổi; đổi HLV; phòng bảo trì; HLV điểm danh → chặn do vắng nhiều lần
A17: 7. Manager xem nhật ký thao tác, dashboard báo cáo và xuất tệp

Sheet Ngoài kế hoạch
A1: VIỆC THÊM THEO GÓP Ý GIẢNG VIÊN – KHÔNG THUỘC SPRINT PLAN, KHÔNG TÍNH VÀO TỔNG HỢP
A2: Việc thêm theo góp ý giảng viên, chuyển từ Sprint 2 và đã làm xong ở sprint bổ sung (PR #3). Đã tính trong Task Sprint 3 nên không tính vào Tổng hợp. Người làm là đề xuất, nhóm chốt lại.
A4: Task ID | B4: Loại | C4: Việc | D4: Người làm (đề xuất) | E4: Trạng thái | F4: Ghi chú
A5: X-01 | B5: BE | C5: Mailer dùng chung (nodemailer, đọc MAIL_* từ .env) | D5: Nhanh | E5: Review | F5: Đã làm: gửi mail qua MAIL_* trong .env (dùng chung cho đặt lại mật khẩu, xác minh, đổi email). Xem S3-01
A6: X-02 | B6: BE | C6: Gửi link xác minh sau đăng ký (token băm, dùng 1 lần, hạn đọc từ system_settings) | D6: Nhanh | E6: Review | F6: Đã làm. Xem S3-28
A7: X-03 | B7: BE | C7: API verify-email, resend-verification (giới hạn tần suất) | D7: Nhanh | E7: Review | F7: Đã làm (có giới hạn tần suất). Xem S3-28
A8: X-04 | B8: BE | C8: Cột email_verified_at + chặn đăng ký lớp/mua gói khi chưa xác minh | D8: Nhanh | E8: Review | F8: Đã chốt: chặn đăng nhập khi chưa xác minh (403 EMAIL_NOT_VERIFIED). Xem S3-28
A9: X-05 | B9: FE | C9: Trang /verify-email, banner chưa xác minh, nút gửi lại | D9: Khôi | E9: Review | F9: Đã làm. Xem S3-29
