Workbook

Sheet Tổng quan đề tài
A1: SWP391 – ĐỀ TÀI 4: HỆ THỐNG QUẢN LÝ TRUNG TÂM THỂ THAO (SPORTS CENTER MANAGEMENT SYSTEM)
A2: Actor, chức năng và các flow của đề tài. Số liệu ở bảng Flow tự tính từ tab Phân chia UC.
A4: 1. Actor và chức năng
A5: Actor | B5: Vai trò | C5: Chức năng
A6: Center Manager | B6: Quản lý trung tâm | C6: + Quản lý danh sách thành viên, huấn luyện viên và nhân viên của trung tâm.
C7: + Quản lý các lớp học, bộ môn, phòng tập và lịch hoạt động.
C8: + Phân công huấn luyện viên phụ trách từng lớp học.
C9: + Xem báo cáo số lượng thành viên, tình trạng đăng ký lớp và doanh thu theo thời gian.
C10: + Quản lý các gói thành viên, học phí và thời hạn sử dụng.
C11: + Phân quyền truy cập hệ thống cho từng vai trò.
C12: + Xem lịch sử thao tác quan trọng trên hệ thống.
A13: Coach | B13: Huấn luyện viên | C13: + Xem lịch dạy và danh sách học viên trong các lớp phụ trách.
C14: + Xem thông tin cơ bản và mục tiêu tập luyện của từng học viên.
C15: + Tạo kế hoạch tập luyện cho cá nhân hoặc cho cả lớp.
C16: + Ghi nhận kết quả tập luyện của học viên sau mỗi buổi.
C17: + Đánh giá tiến độ của học viên và ghi nhận nhận xét.
C18: + Điểm danh học viên trong từng buổi tập.
C19: + Gửi thông báo hoặc bài tập về nhà cho học viên.
C20: + Sử dụng AI để gợi ý bài tập phù hợp dựa trên mục tiêu, trình độ và lịch sử tập luyện của học viên.
A21: Member | B21: Học viên / Thành viên | C21: + Đăng ký tài khoản và cập nhật thông tin cá nhân.
C22: + Xem các gói thành viên và đăng ký/gia hạn gói tập.
C23: + Xem danh sách các lớp học và lịch học.
C24: + Đăng ký hoặc hủy đăng ký lớp học.
C25: + Xem lịch tập cá nhân và thông tin huấn luyện viên.
C26: + Xem lịch sử điểm danh và kết quả tập luyện.
C27: + Xem kế hoạch tập luyện và nhận xét từ huấn luyện viên.
C28: + Gửi câu hỏi cho hệ thống AI về lịch tập, bài tập hoặc các dịch vụ của trung tâm.
C29: + Nhận thông báo về lịch học, thay đổi lịch hoặc thời hạn gói thành viên.
A30: Receptionist | B30: Nhân viên lễ tân | C30: + Tìm kiếm và xem thông tin thành viên.
C31: + Đăng ký thành viên mới tại quầy.
C32: + Quản lý đăng ký/gia hạn các gói thành viên.
C33: + Kiểm tra trạng thái gói tập và thời hạn sử dụng của thành viên.
C34: + Điểm danh thành viên khi đến trung tâm.
C35: + Đăng ký lớp học hoặc hỗ trợ hủy lớp cho thành viên.
C36: + Ghi nhận các khoản thanh toán và in/xuất hóa đơn.
C37: + Tiếp nhận và ghi nhận các yêu cầu hỗ trợ từ thành viên.
A39: 2. Các flow
A40: Flow | B40: Tên flow | C40: Loại | D40: Sprint | E40: Số function | F40: Xong | G40: Chờ review | H40: Chưa làm
A41: Flow 1 | B41: User and membership management | C41: Bắt buộc | D41: Sprint 1 (+ làm sâu ngoại lệ ở Sprint 3) | E41: =COUNTIF('Phân chia UC'!$B$5:$B$113,"Flow 1 – User & Membership") | F41: =COUNTIFS('Phân chia UC'!$B$5:$B$113,"Flow 1 – User & Membership",'Phân chia UC'!$N$5:$N$113,"Done") | G41: =COUNTIFS('Phân chia UC'!$B$5:$B$113,"Flow 1 – User & Membership",'Phân chia UC'!$N$5:$N$113,"Review") | H41: =COUNTIFS('Phân chia UC'!$B$5:$B$113,"Flow 1 – User & Membership",'Phân chia UC'!$N$5:$N$113,"To Do")
A42: Flow 2 | B42: Class booking and schedule management | C42: Bắt buộc | D42: Sprint 2 (+ đổi/huỷ buổi, danh sách chờ, ngoại lệ ở Sprint 3) | E42: =COUNTIF('Phân chia UC'!$B$5:$B$113,"Flow 2 – Class Booking & Schedule") | F42: =COUNTIFS('Phân chia UC'!$B$5:$B$113,"Flow 2 – Class Booking & Schedule",'Phân chia UC'!$N$5:$N$113,"Done") | G42: =COUNTIFS('Phân chia UC'!$B$5:$B$113,"Flow 2 – Class Booking & Schedule",'Phân chia UC'!$N$5:$N$113,"Review") | H42: =COUNTIFS('Phân chia UC'!$B$5:$B$113,"Flow 2 – Class Booking & Schedule",'Phân chia UC'!$N$5:$N$113,"To Do")
...

Sheet Phân chia UC
A1: SWP391 – USE CASE POINT & SPRINT PLAN | PHÂN CHIA VAI TRÒ
A2: Bảng chi tiết 109 function • Sprint 1–4 • cột Flow/Actor/ERD đã sửa lại theo đúng mã UC (bản trước bị lệch dòng) • mô tả và quy tắc theo SPRINT PLAN v3, BUSINESS RULES và đặc tả UC bổ sung 14/10/2026
A3: Sprint 1–2 đã xong 100% và đã merge main. #77–87 là phần Nhanh làm trước Sprint 3 (13–14/10, PR #3). Sprint 3 được chia lại 14/10: Nhanh tập trung SePay đối soát (#88–96); kéo điểm danh #62–64 từ Sprint 4 xuống; thêm ngoại lệ làm sâu Flow 1 (#98–102) và Flow 2 (#103–108). Task sửa UI từ rà soát ảnh chụp nằm ở task sheet Sprint 3. * = bảng có trong project/đề xuất nhưng không có trên ảnh ERD conceptual.
A4: # | B4: Flow | C4: US | D4: Function / Screen (Mô tả) | E4: Actor / Role | F4: N | G4: Level | H4: BE | I4: FE | J4: Sprint | K4: From–To | L4: ERD entities | M4: Business Rule / Notes (Giải thích) | N4: Trạng thái | O4: Nhánh / PR
A5: 1 | B5: Flow 1 – User & Membership | C5: UC-UM-11 | D5: Đăng nhập (màn 1): người dùng nhập email hoặc số điện thoại và mật khẩu; hệ thống xác thực tài khoản, kiểm tra trạng thái và tạo phiên truy cập theo quyền được cấp. | E5: Tất cả tài khoản | F5: 1 | G5: Simple | H5: Nhanh | I5: Khôi | J5: Sprint 1 | K5: 21/09 → 05/10 | L5: USER, ROLE | M5: BR-1.9: tài khoản bị khoá không đăng nhập được và phiên/token cũ bị từ chối ở request kế tiếp. Email/SĐT được chuẩn hoá theo BR-1.10; sai thông tin trả thông báo chung, không làm lộ tài khoản. Token hết hạn trả 401; thao tác quan trọng ghi audit theo BR-0.2. | N5: Done | O5: sprint-1/be-nhanh, sprint-1/fe-khoi (đã merge main)
A6: 2 | B6: Flow 1 – User & Membership | C6: UC-UM-11 | D6: Đăng xuất / nạp quyền (màn 2): kết thúc phiên hiện tại và nạp role/permission hiện hành để màn hình/API quyết định thao tác được phép. | E6: Tất cả tài khoản | F6: 2 | G6: Simple | H6: Nhanh | I6: Khôi | J6: Sprint 1 | K6: 21/09 → 05/10 | L6: USER, ROLE, PERMISSION | M6: Role/permission phải đọc từ DB hoặc cache theo request, không hard-code trong token. Quyền bị thu hồi có hiệu lực ở request kế tiếp và trả 403; logout phải kết thúc phiên hiện tại, không giữ quyền sau khi đăng xuất. | N6: Done | O6: sprint-1/be-nhanh, sprint-1/fe-khoi (đã merge main)
A7: 3 | B7: Flow 1 – User & Membership | C7: UC-UM-09 | D7: Danh sách tài khoản (màn 8): người có quyền quản trị xem, tìm và lọc tài khoản theo tên, email/SĐT, role và trạng thái ACTIVE/LOCKED. | E7: Center Manager | F7: 3 | G7: Simple | H7: Nhanh | I7: Khôi | J7: Sprint 1 | K7: 21/09 → 05/10 | L7: USER, ROLE | M7: Chỉ người có permission user.read/user.manage được xem. Hiển thị tên, email/SĐT đã chuẩn hoá, role và trạng thái ACTIVE/LOCKED; tài khoản đã phát sinh dữ liệu không được xoá cứng, thay đổi quan trọng ghi audit theo BR-0.1/0.2. | N7: Done | O7: sprint-1/be-nhanh, sprint-1/fe-khoi (đã merge main)
A8: 4 | B8: Flow 1 – User & Membership | C8: UC-UM-09 | D8: Tạo tài khoản nhân viên (màn 8): Manager nhập thông tin nhân viên, tạo tài khoản và gán role phù hợp để nhân viên có thể đăng nhập và sử dụng chức năng được cấp. | E8: Center Manager | F8: 4 | G8: Simple | H8: Nhanh | I8: Khôi | J8: Sprint 1 | K8: 21/09 → 05/10 | L8: USER, ROLE, AUDIT_LOG* | M8: BR-1.1/1.10: email và SĐT duy nhất, email chuẩn hoá, SĐT đúng định dạng Việt Nam. Chỉ Manager tạo tài khoản nhân viên và gán role hợp lệ; tài khoản nhân viên không được tự cấp quyền; dữ liệu đăng nhập phải được xử lý an toàn. | N8: Done | O8: sprint-1/be-nhanh, sprint-1/fe-khoi (đã merge main)
A9: 5 | B9: Flow 1 – User & Membership | C9: UC-UM-09 | D9: Khoá / đổi role tài khoản (màn 8): Manager khoá/mở khoá tài khoản hoặc thay đổi role; hệ thống cập nhật quyền và trạng thái truy cập của tài khoản. | E9: Center Manager | F9: 5 | G9: Medium | H9: Nhanh | I9: Khôi | J9: Sprint 1 | K9: 21/09 → 05/10 | L9: USER, ROLE, AUDIT_LOG* | M9: Chỉ Manager có quyền và không được tự khoá/đổi role chính mình. BR-1.9: khoá tài khoản thì request sau bị từ chối; coach đang dạy lớp OPEN phải chuyển lớp trước theo BR-2.13; không xoá cứng và phải ghi audit người thực hiện, thời điểm, thay đổi theo BR-0.1/0.2. | N9: Done | O9: sprint-1/be-nhanh, sprint-1/fe-khoi (đã merge main)
A10: 6 | B10: Flow 1 – User & Membership | C10: UC-UM-18 | D10: Danh sách role và ma trận quyền (màn 8): hiển thị các role, permission thuộc từng role và role mặc định dùng cho đăng ký tài khoản mới. | E10: Center Manager | F10: 6 | G10: Simple | H10: Nhanh | I10: Khôi | J10: Sprint 1 | K10: 21/09 → 05/10 | L10: ROLE, PERMISSION | M10: Chỉ Manager hoặc permission role.read được xem ma trận. Ma trận phải phản ánh role/permission đang lưu và role mặc định hiện hành; quyền bị thu hồi có hiệu lực ở request kế tiếp. | N10: Done | O10: sprint-1/be-nhanh, sprint-1/fe-khoi (đã merge main)
A11: 7 | B11: Flow 1 – User & Membership | C11: UC-UM-18 | D11: Tạo / sửa role, gán quyền (màn 8): Manager tạo hoặc cập nhật role, chọn các permission hợp lệ và lưu ma trận quyền áp dụng cho người dùng. | E11: Center Manager | F11: 7 | G11: Simple | H11: Nhanh | I11: Khôi | J11: Sprint 1 | K11: 21/09 → 05/10 | L11: ROLE, PERMISSION, AUDIT_LOG* | M11: Mã permission phải thuộc registry, mỗi role có tên duy nhất. Thay đổi có hiệu lực từ request kế tiếp, không cần đăng nhập lại; không cho gán quyền vượt phạm vi người thao tác và ghi audit giá trị cũ/mới theo BR-0.2. | N11: Done | O11: sprint-1/be-nhanh, sprint-1/fe-khoi (đã merge main)
A12: 8 | B12: Flow 1 – User & Membership | C12: UC-UM-18 | D12: Xoá role / đặt mặc định (màn 8): Manager ngừng sử dụng role không còn cần thiết và chọn role mặc định cho tài khoản tự đăng ký. | E12: Center Manager | F12: 8 | G12: Medium | H12: Nhanh | I12: Khôi | J12: Sprint 1 | K12: 21/09 → 05/10 | L12: ROLE, USER, AUDIT_LOG* | M12: Role hệ thống hoặc role đang được user tham chiếu không được xoá cứng; dùng ngừng hoạt động theo BR-0.1. Hệ thống phải duy trì đúng một role mặc định cho đăng ký tự do theo BR-1.8 và audit thay đổi. | N12: Done | O12: sprint-1/be-nhanh, sprint-1/fe-khoi (đã merge main)
A13: 9 | B13: Flow 1 – User & Membership | C13: UC-UM-01 | D13: Đăng ký tài khoản (màn 1): người dùng nhập thông tin định danh và mật khẩu; hệ thống tạo tài khoản Member, gán role mặc định và báo kết quả đăng ký. | E13: Member (khách) | F13: 9 | G13: Simple | H13: Nhanh | I13: Khôi | J13: Sprint 1 | K13: 21/09 → 05/10 | L13: USER, ROLE | M13: BR-1.1/1.10: email/SĐT duy nhất và chuẩn hoá; mật khẩu tối thiểu 8 ký tự, lưu dạng mã hoá theo BR-1.7. Người đăng ký không chọn role; hệ thống gán role mặc định trong DB theo BR-1.8; dữ liệu trùng phải báo rõ. | N13: Done | O13: sprint-1/be-nhanh, sprint-1/fe-khoi (đã merge main)
A14: 10 | B14: Flow 1 – User & Membership | C14: UC-UM-13 | D14: Đổi mật khẩu (màn S20): người dùng nhập mật khẩu hiện tại và mật khẩu mới; hệ thống kiểm tra mật khẩu cũ rồi cập nhật mật khẩu mới an toàn. | E14: Tất cả tài khoản | F14: 10 | G14: Medium | H14: Nhanh | I14: Khôi | J14: Sprint 1 | K14: 21/09 → 05/10 | L14: USER, AUDIT_LOG* | M14: Phải nhập đúng mật khẩu cũ; mật khẩu mới tối thiểu 8 ký tự và được mã hoá theo BR-1.7. Không ghi mật khẩu vào log; phiên/token cũ được xử lý theo chính sách bảo mật và thao tác đổi mật khẩu được audit. | N14: Done | O14: sprint-1/be-nhanh, sprint-1/fe-khoi (đã merge main)
A15: 11 | B15: Flow 1 – User & Membership | C15: UC-UM-02 | D15: Xem hồ sơ cá nhân (màn 3): người dùng xem thông tin liên hệ, trạng thái tài khoản và membership của chính tài khoản đang đăng nhập. | E15: Tất cả tài khoản | F15: 11 | G15: Simple | H15: Nhanh | I15: Khôi | J15: Sprint 1 | K15: 21/09 → 05/10 | L15: USER, MEMBERSHIP | M15: Chỉ trả hồ sơ của tài khoản đang đăng nhập: thông tin liên hệ, trạng thái và membership của chính người đó. Khi chỉ có read_own thì không được đọc hồ sơ khác; dữ liệu nhạy cảm phải tuân thủ permission. | N15: Done | O15: sprint-1/be-nhanh, sprint-1/fe-khoi (đã merge main)
A16: 12 | B16: Flow 1 – User & Membership | C16: UC-UM-02 | D16: Cập nhật hồ sơ cá nhân (màn S20): người dùng sửa các trường hồ sơ được phép như tên, email hoặc số điện thoại; hệ thống kiểm tra dữ liệu trước khi lưu. | E16: Tất cả tài khoản | F16: 12 | G16: Simple | H16: Nhanh | I16: Khôi | J16: Sprint 1 | K16: 21/09 → 05/10 | L16: USER, AUDIT_LOG* | M16: Chỉ sửa các trường hồ sơ được phép, không tự đổi role hoặc trạng thái tài khoản. Email/SĐT mới phải chuẩn hoá và không trùng theo BR-1.1/1.10; lưu người sửa, thời điểm và giá trị cũ/mới theo BR-0.2. | N16: Done | O16: sprint-1/be-nhanh, sprint-1/fe-khoi (đã merge main)
... A113: 109 | B113: Khác – Tài liệu & chất lượng | C113: Tài liệu | D113: Bổ sung đặc tả UC-PAY-11 đến 14, UC-UM-20, UC-CB-19, UC-CB-20; business rule BR-1.14 đến 1.17, BR-2.16, 2.17, BR-PAY-15 đến 20; sơ đồ flow 1.5, 2.9, 3.17, 3.18; báo cáo rà soát UI Flow 1, 2. | E113: — | F113: 109 | G113: Simple | H113: Nhanh | I113: — | J113: Sprint 3 | K113: 13/10 → 14/10 (bổ sung) | L113: — | M113: Không có business rule riêng; tài liệu là nguồn cho các task #88–#108. | N113: Review | O113: feature/f3-sepay-online-payment

Sheet Sprint Summary
A1: SPRINT SUMMARY – USE CASE POINT v3 (đã gộp Sprint 0 vào Sprint 1)
A2: Tổng hợp tự động từ tab Phân chia UC: 109 function. Kế hoạch gốc v3 (22/09/2026) có 76 function; #77–87 Nhanh làm trước Sprint 3; #88–109 bổ sung 14/10/2026 (SePay đối soát, ngoại lệ Flow 1, 2, kiểm thử, tài liệu).
A4: Sprint | B4: From–To | C4: BE | D4: FE | E4: Số function | F4: Simple | G4: Medium | H4: Complex | I4: Phạm vi / ghi chú | J4: To Do | K4: In Progress | L4: Review | M4: Done
A5: Sprint 1 | B5: 21/09 → 05/10 | C5: Nhanh / Bảo | D5: Khôi / Khải | E5: =COUNTIF('Phân chia UC'!$J$5:$J$113,$A5) | F5: =COUNTIFS('Phân chia UC'!$J$5:$J$113,$A5,'Phân chia UC'!$G$5:$G$113,F$4) | G5: =COUNTIFS('Phân chia UC'!$J$5:$J$113,$A5,'Phân chia UC'!$G$5:$G$113,G$4) | H5: =COUNTIFS('Phân chia UC'!$J$5:$J$113,$A5,'Phân chia UC'!$G$5:$G$113,H$4) | I5: Flow 1 + UC-PAY-06/07/10. Nhanh + Khôi: #1–12, #22–28; Bảo + Khải: #13–21. Đã xong, đã merge main. | J5: =COUNTIFS('Phân chia UC'!$J$5:$J$113,$A5,'Phân chia UC'!$N$5:$N$113,J$4) | K5: =COUNTIFS('Phân chia UC'!$J$5:$J$113,$A5,'Phân chia UC'!$N$5:$N$113,K$4) | L5: =COUNTIFS('Phân chia UC'!$J$5:$J$113,$A5,'Phân chia UC'!$N$5:$N$113,L$4) | M5: =COUNTIFS('Phân chia UC'!$J$5:$J$113,$A5,'Phân chia UC'!$N$5:$N$113,M$4)
A6: Sprint 2 | B6: 06/10 → 19/10 | C6: Bảo / Nhanh | D6: Khải / Khôi | E6: =COUNTIF('Phân chia UC'!$J$5:$J$113,$A6) | F6: =COUNTIFS('Phân chia UC'!$J$5:$J$113,$A6,'Phân chia UC'!$G$5:$G$113,F$4) | G6: =COUNTIFS('Phân chia UC'!$J$5:$J$113,$A6,'Phân chia UC'!$G$5:$G$113,G$4) | H6: =COUNTIFS('Phân chia UC'!$J$5:$J$113,$A6,'Phân chia UC'!$G$5:$G$113,H$4) | I6: Flow 2. Bảo + Khải: #29–37; Nhanh + Khôi: #38–46. Đã xong, đã merge main. | J6: =COUNTIFS('Phân chia UC'!$J$5:$J$113,$A6,'Phân chia UC'!$N$5:$N$113,J$4) | K6: =COUNTIFS('Phân chia UC'!$J$5:$J$113,$A6,'Phân chia UC'!$N$5:$N$113,K$4) | L6: =COUNTIFS('Phân chia UC'!$J$5:$J$113,$A6,'Phân chia UC'!$N$5:$N$113,L$4) | M6: =COUNTIFS('Phân chia UC'!$J$5:$J$113,$A6,'Phân chia UC'!$N$5:$N$113,M$4)
A7: Sprint 3 | B7: 20/10 → 02/11 | C7: Bảo / Nhanh | D7: Khôi / Khải | E7: =COUNTIF('Phân chia UC'!$J$5:$J$113,$A7) | F7: =COUNTIFS('Phân chia UC'!$J$5:$J$113,$A7,'Phân chia UC'!$G$5:$G$113,F$4) | G7: =COUNTIFS('Phân chia UC'!$J$5:$J$113,$A7,'Phân chia UC'!$G$5:$G$113,G$4) | H7: =COUNTIFS('Phân chia UC'!$J$5:$J$113,$A7,'Phân chia UC'!$G$5:$G$113,H$4) | I7: BE: Nhanh SePay/đối soát #56–59, #88–96, #102; Bảo #50, #52, #53, #60–63, #100, #101, #103, #105–107. Khải full-stack #51, #99, #104 + test #108; Khôi full-stack #64, #98 + test #97. FE: Khải #51, #57, #58, #62, #88, #90–92, #95, #99, #101, #103, #104, #107 + 17 task UI; Khôi #52, #53, #59–61, #63, #64, #89, #93, #98, #100, #105, #106 + 13 task UI. #77–87 Nhanh đã làm (PR #3). | J7: =COUNTIFS('Phân chia UC'!$J$5:$J$113,$A7,'Phân chia UC'!$N$5:$N$113,J$4) | K7: =COUNTIFS('Phân chia UC'!$J$5:$J$113,$A7,'Phân chia UC'!$N$5:$N$113,K$4) | L7: =COUNTIFS('Phân chia UC'!$J$5:$J$113,$A7,'Phân chia UC'!$N$5:$N$113,L$4) | M7: =COUNTIFS('Phân chia UC'!$J$5:$J$113,$A7,'Phân chia UC'!$N$5:$N$113,M$4)
A8: Sprint 4 | B8: 03/11 → 16/11 | C8: Bảo / Nhanh | D8: Khôi / Khải | E8: =COUNTIF('Phân chia UC'!$J$5:$J$113,$A8) | F8: =COUNTIFS('Phân chia UC'!$J$5:$J$113,$A8,'Phân chia UC'!$G$5:$G$113,F$4) | G8: =COUNTIFS('Phân chia UC'!$J$5:$J$113,$A8,'Phân chia UC'!$G$5:$G$113,G$4) | H8: =COUNTIFS('Phân chia UC'!$J$5:$J$113,$A8,'Phân chia UC'!$G$5:$G$113,H$4) | I8: Training/kế hoạch tập #65–69 do Bảo; AI #70–76 do Nhanh; điểm danh #62–64 đã kéo lên Sprint 3. | J8: =COUNTIFS('Phân chia UC'!$J$5:$J$113,$A8,'Phân chia UC'!$N$5:$N$113,J$4) | K8: =COUNTIFS('Phân chia UC'!$J$5:$J$113,$A8,'Phân chia UC'!$N$5:$N$113,K$4) | L8: =COUNTIFS('Phân chia UC'!$J$5:$J$113,$A8,'Phân chia UC'!$N$5:$N$113,L$4) | M8: =COUNTIFS('Phân chia UC'!$J$5:$J$113,$A8,'Phân chia UC'!$N$5:$N$113,M$4)
A9: Tổng | E9: =SUM(E5:E8) | F9: =SUM(F5:F8) | G9: =SUM(G5:G8) | H9: =SUM(H5:H8) | J9: =SUM(J5:J8) | K9: =SUM(K5:K8) | L9: =SUM(L5:L8) | M9: =SUM(M5:M8)
A14: Thành viên | B14: BE functions | C14: FE functions | D14: Vai trò / ghi chú
A15: Nhanh | B15: =COUNTIF('Phân chia UC'!$H$5:$H$113,$A15) | C15: =COUNTIF('Phân chia UC'!$I$5:$I$113,$A15) | D15: Leader. BE Sprint 1–2; Sprint 3 tập trung SePay: webhook, hàng chờ đối soát, map giao dịch, thiếu/thừa, chuyển lặp, báo đã chuyển; AI Sprint 4
A16: Bảo | B16: =COUNTIF('Phân chia UC'!$H$5:$H$113,$A16) | C16: =COUNTIF('Phân chia UC'!$I$5:$I$113,$A16) | D16: BE Sprint 1 (#13–21), Sprint 2 (#29–37); Sprint 3: job gia hạn, đổi/huỷ buổi, báo cáo, điểm danh, bảo lưu, danh sách chờ, đổi HLV, phòng bảo trì, chặn vắng mặt
A17: Khôi | B17: =COUNTIF('Phân chia UC'!$H$5:$H$113,$A17) | C17: =COUNTIF('Phân chia UC'!$I$5:$I$113,$A17) | D17: FE Sprint 1–2 (#1–12, #22–28, #38–46); Sprint 3: đổi/huỷ buổi, báo cáo, hoàn tiền, chuyển bù, báo đã chuyển, điểm danh, khoá đăng nhập + 13 task sửa UI, test E2E SePay
A18: Khải | B18: =COUNTIF('Phân chia UC'!$H$5:$H$113,$A18) | C18: =COUNTIF('Phân chia UC'!$I$5:$I$113,$A18) | D18: FE Sprint 1–2 (#13–21, #29–37); Sprint 3 nhiều UI nhất: hàng chờ đối soát, map giao dịch, cảnh báo chuyển lặp, mẫu hoá đơn PDF, nhật ký thao tác, bảo lưu, danh sách chờ + 17 task sửa UI, test E2E Flow 1, 2
A21: ="Kiểm tra tổng: "&E9&" function = "&F9&" Simple + "&G9&" Medium + "&H9&" Complex; đã xong "&M9&", chờ review "&L9&", chưa làm "&J9&". Job/webhook/system rows không có FE được giữ là —."

Sheet Sources & Notes
A1: SOURCES & NOTES – PHẠM VI, NGUỒN VÀ QUY ƯỚC (v3, đã gộp Sprint 0 vào Sprint 1)
A3: Nguồn | B3: Loại | C3: Đường dẫn / mô tả
A4: SWP391_Sprint_Plan.docx | B4: Nguồn chính – v3 | C4: https://docs.google.com/document/d/1MBRajtQfgI1SQWpi68lWTdA3X7Xq7KvV/edit — SPRINT PLAN – USE CASE POINT v3, 22/09/2026
A5: ERD-Conceptal.png | B5: ERD tham chiếu | C5: https://drive.google.com/file/d/1EPF9Ax0Twfgsw1utJFDYKTvnTdeh5mmp/view — entity/relationship conceptual gửi kèm
A6: SWP391_BaoCaoTuan1_MVP_HighFidelity_HoanThien.docx | B6: Project data | C6: Actor matrix, màn hình, business rule, RBAC, SePay, training và AI trong project
A7: SWP391_Tuan1_Leader_Plan_Sports_Center.docx | B7: Project data | C7: Vai trò nhóm, actor/feature coverage và quy ước triển khai tuần 1
A8: 07_Business_Rules.docx | B8: Business rules – nguồn bổ sung | C8: https://docs.google.com/document/d/1hbthAJPq1EQtrmuFvD8OXe7OFAry3kMM/edit — BR-0.x, BR-1.x, BR-2.x, BR-3.x, BR-PAY-xx và BR-AI-xx
A10: Quy ước phân công | B10: Giá trị | C10: Ghi chú
A11: Sprint 1 | B11: BE Nhanh + Bảo | FE Khôi + Khải | C11: 21/09 → 05/10; Flow 1 + UC-PAY-06/07/10; 28 function #1–28; Nhanh + Khôi #1–12, #22–28; Bảo + Khải #13–21. ĐÃ XONG.
A12: Sprint 2 | B12: BE Bảo + Nhanh | FE Khải + Khôi | C12: 06/10 → 19/10; Flow 2; 18 function #29–46; Bảo + Khải #29–37, Nhanh + Khôi #38–46. ĐÃ XONG.
A13: Sprint 3 | B13: BE Bảo + Nhanh | FE Khôi + Khải | C13: 20/10 → 02/11; chia lại 14/10 để Bảo, Khôi, Khải làm nhiều hơn: Nhanh chỉ giữ SePay/đối soát; kéo #62–64 từ Sprint 4; thêm ngoại lệ Flow 1, 2 (#98–108) và 30 task sửa UI từ rà soát ảnh chụp.
A14: Sprint 4 | B14: BE Bảo / Nhanh | FE Khôi | C14: 03/11 → 16/11; Training #65–69 do Bảo; AI #70–76 do Nhanh; FE Khôi/Khải.
A15: Bổ sung | B15: BE + FE Nhanh | C15: 13/10 → 14/10 làm trước Sprint 3, thuộc Sprint 3 (#77–87); nằm trong PR #3, chờ review
... A24: Project extensions | B24: * | C24: AUDIT_LOG, SYSTEM_SETTING, PAYMENT_WEBHOOK_LOG, EMAIL_VERIFICATION_TOKEN được dùng trong project; không hiện trong ảnh conceptual gửi kèm
A26: Cập nhật 14/10/2026 (lần 2): sửa cột Flow/Actor/ERD bị lệch dòng; Sprint 1–2 chốt Done; chia lại Sprint 3; thêm #88–109 (SePay đối soát, ngoại lệ Flow 1, 2, kiểm thử, tài liệu).
A27: Method note: Attachment photo is layout reference only. The authoritative content for this revision is SPRINT PLAN v3 + BUSINESS RULES – TỔNG HỢP plus the existing ERD/project mapping; Function/Screen and Business Rule/Notes are intentionally expanded for reader clarity.
